package com.atguigu.chapter12

import scala.util.control.Breaks._

object Test08 {
  def main(args: Array[String]): Unit = {

//    try{
//      val res = 5 / 0
//    }catch {
//      case e:ArithmeticException => println("算数异常")
//      case _ => println("other exception")
//    }finally {
//      println("running is finished")
//    }


  }
}
